Workbook

Sheet trash_hauler_report
A1: Request Number | B1: Date Opened | C1: Request | D1: Description | E1: Incident Address | F1: Not | G1: Not | S1: Zip Code | T1: Trash Hauler | U1: Trash Route | V1: Council District | W1: State Plan X | X1: State Plan Y
A2: 25270 | B2: 43040 | C2: Trash - Backdoor | D2: house with the wheel chair ramp, they share driveway, in back driveway. 3817 Crouch Dr near NES light post is. 615-876-6274 | E2: 3817 Crouch Dr | F2: =SEARCH($G$1,D2,1) -> #VALUE! | G2: D2 | H2: 1) | S2: 37207 | T2: RED RIVER | U2: 3205 | V2: 2 | W2: 1727970.4 | X2: 686779.48
A3: 25274 | B3: 43040 | C3: Trash - Curbside/Alley Missed Pickup | D3: Curb/Trash miss Tuesday. | E3: 4028 Clarksville Pike | F3: =SEARCH($G$1,D3,1) -> #VALUE! | G3: =SEARCH($G$1,D3,1) -> #VALUE! | S3: 37218 | T3: RED RIVER | U3: 4202 | V3: 1 | W3: 1721259.4 | X3: 685444.8
A4: 25276 | B4: 43040 | C4: Trash - Curbside/Alley Missed Pickup | D4: Curb/trash miss Tuesday. | E4: 6528 Thunderbird Dr | F4: =SEARCH($G$1,D4,1) -> #VALUE! | G4: =SEARCH($G$1,D4,1) -> #VALUE! | S4: 37209 | T4: RED RIVER | U4: 4205 | V4: 20 | W4: 1707026.8 | X4: 659887.47
A5: 25307 | B5: 43040 | C5: Trash - Curbside/Alley Missed Pickup | D5: missed | E5: 2603 old matthews rd | F5: =SEARCH($G$1,D5,1) -> #VALUE! | G5: =SEARCH($G$1,D5,1) -> #VALUE! | S5: 37207 | T5: WASTE IND | U5: 2206 | V5: 2 | W5: 1735691.8 | X5: 685027.25
A6: 25312 | B6: 43040 | C6: Trash - Curbside/Alley Missed Pickup | D6: Missed the even side of the road. | E6: 604 croley dr | F6: =SEARCH($G$1,D6,1) -> #VALUE! | G6: =SEARCH($G$1,D6,1) -> #VALUE! | S6: 37209 | T6: RED RIVER | U6: 4203 | V6: 20 | W6: 1710185.8 | X6: 664205.1
A7: 25317 | B7: 43040 | C7: Trash Collection Complaint | D7: left trash cart in middle of driveway instead of at the backdoor pickup spot | E7: 3602 floral dr | F7: =SEARCH($G$1,D7,1) -> #VALUE! | G7: =SEARCH($G$1,D7,1) -> #VALUE! | S7: 37211 | T7: RED RIVER | U7: 4304 | V7: 16 | W7: 1751660.2 | X7: 643215.2
A8: 25325 | B8: 43040 | C8: Damage to Property | D8: Trash/emptied Wednesday & now metal black-mailbox damage. customer wants call back and fix and replace. | E8: 4721 Chalmers Dr | F8: =SEARCH($G$1,D8,1) -> #VALUE! | G8: =SEARCH($G$1,D8,1) -> #VALUE! | S8: 37215 | T8: RED RIVER | U8: 3303 | V8: 34 | W8: 1726301 | X8: 637078.4
A9: 25327 | B9: 43040 | C9: Trash Collection Complaint | D9: Trash out on time, miss again Tuesday. ALLEY | E9: 1816 Jo Johnston Ave | F9: =SEARCH($G$1,D9,1) -> #VALUE! | G9: =SEARCH($G$1,D9,1) -> #VALUE! | S9: 37203 | T9: METRO | U9: 9208 | V9: 21 | W9: 1731459.4 | X9: 666013.6
A10: 25330 | B10: 43040 | C10: Trash - Curbside/Alley Missed Pickup | D10: Missed. | E10: 4484 Lavergne Couchville Pike | F10: =SEARCH($G$1,D10,1) -> #VALUE! | G10: =SEARCH($G$1,D10,1) -> #VALUE! | S10: 37013 | T10: RED RIVER | U10: 4210 | V10: 33 | W10: 1794533.5 | X10: 618749.34
A11: 25331 | B11: 43040 | C11: Trash - Curbside/Alley Missed Pickup | D11: Trash missed Tuesday again, ALLEY | E11: 1206 Ireland St | F11: =SEARCH($G$1,D11,1) -> #VALUE! | G11: =SEARCH($G$1,D11,1) -> #VALUE! | S11: 37208 | T11: METRO | U11: 9208 | V11: 19 | W11: 1733029.5 | X11: 668762.64
A12: 25341 | B12: 43040 | C12: Trash - Curbside/Alley Missed Pickup | D12: Missed trash pickup - resident has at curb for pick up today received back door form on 10/30/2017 is still in interoffice mail pickup since 10/30 | E12: 3113 HYDES FERRY RD | F12: =SEARCH($G$1,D12,1) -> #VALUE! | G12: =SEARCH($G$1,D12,1) -> #VALUE! | S12: 37218 | T12: RED RIVER | U12: 4204 | V12: 2 | W12: 1721577.8 | X12: 676018.4
A13: 25350 | B13: 43040 | C13: Trash Collection Complaint | D13: Missed- 4th week in a row. | E13: 3210 Whites Creek Pike | F13: =SEARCH($G$1,D13,1) -> #VALUE! | G13: =SEARCH($G$1,D13,1) -> #VALUE! | S13: 37207 | T13: RED RIVER | U13: 3201 | V13: 3 | W13: 1726433 | X13: 691919.2
A14: 25359 | B14: 43040 | C14: Trash - Curbside/Alley Missed Pickup | D14: Missed. Does not have access to alley. | E14: 830 Meridian St | F14: =SEARCH($G$1,D14,1) -> 14 | G14: =SEARCH($G$1,D14,1) -> 14 | S14: 37207 | T14: METRO | U14: 9207 | V14: 5 | W14: 1741744.7 | X14: 675328.67
... A21: 25454 | B21: 43040 | C21: Trash - Curbside/Alley Missed Pickup | D21: Missed. | E21: 449 Westboro Dr | F21: =SEARCH($G$1,D21,1) -> #VALUE! | G21: =SEARCH($G$1,D21,1) -> #VALUE! | S21: 37209 | T21: RED RIVER | U21: 4201 | V21: 20 | W21: 1710615.1 | X21: 661992.33
A22: 25465 | B22: 43040 | C22: Trash Collection Complaint | D22: A resident is complaining that a trash truck ran a red light through a school zone at Davidson Academy. The truck number is 4887AH. | E22: 1414 Old Hickory Blvd | F22: =SEARCH($G$1,D22,1) -> #VALUE! | G22: =SEARCH($G$1,D22,1) -> #VALUE! | S22: 37207 | V22: 3 | W22: 1738737 | X22: 711231.8
A23: 25469 | B23: 43040 | C23: Trash - Curbside/Alley Missed Pickup | D23: Our trash was not picked up today, Wed, Nov 1. It was out by 7 am and our neighbors trash was picked up but ours was not. | E23: 117 Lafayette Ct | F23: =SEARCH($G$1,D23,1) -> 15 | G23: =SEARCH($G$1,D23,1) -> 15 | S23: 37205 | T23: RED RIVER | U23: 1302 | V23: 23 | W23: 1713465 | X23: 644882.4
A24: 25471 | B24: 43040 | C24: Trash - Curbside/Alley Missed Pickup | D24: Alley trash miss Tuesday, also others as well, out on time. | E24: 1904 MeHarry Blvd | F24: =SEARCH($G$1,D24,1) -> #VALUE! | G24: =SEARCH($G$1,D24,1) -> #VALUE! | S24: 37208 | T24: METRO | U24: 9208 | V24: 21 | W24: 1730048.1 | X24: 668927.19
A25: 25474 | B25: 43040 | C25: Trash - Curbside/Alley Missed Pickup | D25: Customer says backdoor pickup was missed the past 2 weeks | E25: 1144 Sewanee Rd | F25: =SEARCH($G$1,D25,1) -> #VALUE! | G25: =SEARCH($G$1,D25,1) -> #VALUE! | S25: 37220 | T25: RED RIVER | U25: 3302 | V25: 34 | W25: 1731663.4 | X25: 639182.4
A26: 25496 | B26: 43040 | C26: Trash - Curbside/Alley Missed Pickup | D26: Missed pickup | E26: 1815 WOODMONT BLVD | F26: =SEARCH($G$1,D26,1) -> #VALUE! | G26: =SEARCH($G$1,D26,1) -> #VALUE! | S26: 37215 | T26: RED RIVER | U26: 3305 | V26: 25 | W26: 1730532.2 | X26: 648861.63
A27: 25506 | B27: 43040 | C27: Trash - Curbside/Alley Missed Pickup | D27: Missed. | E27: 405 Page Rd | F27: =SEARCH($G$1,D27,1) -> #VALUE! | G27: =SEARCH($G$1,D27,1) -> #VALUE! | S27: 37205 | T27: RED RIVER | U27: 1302 | V27: 34 | W27: 1711546.6 | X27: 639925.6
A28: 25507 | B28: 43040 | C28: Trash - Curbside/Alley Missed Pickup | D28: Missed pickup | E28: 4722 DANBY DR | F28: =SEARCH($G$1,D28,1) -> #VALUE! | G28: =SEARCH($G$1,D28,1) -> #VALUE! | S28: 37211 | T28: RED RIVER | U28: 4302 | V28: 26 | W28: 1748482.6 | X28: 636882.4
A29: 25508 | B29: 43040 | C29: Trash Collection Complaint | D29: missed. Neighbor missed as well-say she is at a dead end and she is constantly missed. She understands it is hard for the driver to turn around but she doesn't want to have to call all the time. | E29: 2812 27TH AVE S | F29: =SEARCH($G$1,D29,1) -> #VALUE! | G29: =SEARCH($G$1,D29,1) -> #VALUE! | S29: 37212 | T29: RED RIVER | U29: 2305 | V29: 18 | W29: 1729022.3 | X29: 652985.68
A30: 25509 | B30: 43040 | C30: Trash - Curbside/Alley Missed Pickup | D30: cust says entire street was missed | E30: 4506 DAKOTA AVE | F30: =SEARCH($G$1,D30,1) -> #VALUE! | G30: =SEARCH($G$1,D30,1) -> #VALUE! | S30: 37209 | T30: RED RIVER | U30: 1308 | V30: 24 | W30: 1720100.2 | X30: 661552.8
A31: 25511 | B31: 43040 | C31: Trash - Curbside/Alley Missed Pickup | D31: Missed. | E31: 259 Sunrise Ave | F31: =SEARCH($G$1,D31,1) -> #VALUE! | G31: =SEARCH($G$1,D31,1) -> #VALUE! | S31: 37211 | T31: RED RIVER | U31: 4304 | V31: 16 | W31: 1750609.6 | X31: 645187.68
A32: 25512 | B32: 43040 | C32: Trash - Curbside/Alley Missed Pickup | D32: cust says entire street was missed | E32: 4311 dakota ave | F32: =SEARCH($G$1,D32,1) -> #VALUE! | G32: =SEARCH($G$1,D32,1) -> #VALUE! | S32: 37209 | T32: RED RIVER | U32: 1308 | V32: 24 | W32: 1720100.2 | X32: 661552.8
A33: 25515 | B33: 43040 | C33: Trash - Curbside/Alley Missed Pickup | D33: Missed. Cart is still out | E33: 4029 Graybar Ct | F33: =SEARCH($G$1,D33,1) -> #VALUE! | G33: =SEARCH($G$1,D33,1) -> #VALUE! | S33: 37215 | T33: RED RIVER | U33: 3305 | V33: 25 | W33: 1729986.3 | X33: 648821.43
A34: 25517 | B34: 43040 | C34: Trash - Curbside/Alley Missed Pickup | D34: Missed. | E34: 524 Harding Pl | F34: =SEARCH($G$1,D34,1) -> #VALUE! | G34: =SEARCH($G$1,D34,1) -> #VALUE! | S34: 37211 | T34: RED RIVER | U34: 4302 | V34: 26 | W34: 1751209 | X34: 635651.2
... A44: 25575 | B44: 43041 | C44: Trash - Curbside/Alley Missed Pickup | D44: missed pick up | E44: 346 lynn dr | F44: =SEARCH($G$1,D44,1) -> #VALUE! | G44: =SEARCH($G$1,D44,1) -> #VALUE! | S44: 37211 | T44: RED RIVER | U44: 4302 | V44: 26 | W44: 1747944.1 | X44: 637187.8
A45: 25577 | B45: 43041 | C45: Trash - Curbside/Alley Missed Pickup | D45: trash missed pick up - others missed in area | E45: 4205 arundel ct | F45: =SEARCH($G$1,D45,1) -> #VALUE! | G45: =SEARCH($G$1,D45,1) -> #VALUE! | S45: 37215 | T45: RED RIVER | U45: 2303S | V45: 25 | W45: 1721425 | X45: 648442.07
A46: 25578 | B46: 43041 | C46: Trash Collection Complaint | D46: Curb/Trash missed Whole street, check for other streets as well seen carts still out. Wednesday. Has to keep calling. wants to know why? | E46: 204 Channelkirk Ln | F46: =SEARCH($G$1,D46,1) -> #VALUE! | G46: =SEARCH($G$1,D46,1) -> #VALUE! | S46: 37215 | T46: RED RIVER | U46: 3305 | V46: 25 | W46: 1729598.7 | X46: 648513.73
A47: 25585 | B47: 43041 | C47: Trash - Curbside/Alley Missed Pickup | D47: Curb/Trash miss Wednesday | E47: 200 Channelkirk Ln | F47: =SEARCH($G$1,D47,1) -> #VALUE! | G47: =SEARCH($G$1,D47,1) -> #VALUE! | S47: 37215 | T47: RED RIVER | U47: 3305 | V47: 25 | W47: 1729513.3 | X47: 648495.57
A48: 25586 | B48: 43041 | C48: Trash - Curbside/Alley Missed Pickup | D48: Missed pickup | E48: 4311 dakota ave | F48: =SEARCH($G$1,D48,1) -> #VALUE! | G48: =SEARCH($G$1,D48,1) -> #VALUE! | S48: 37209 | T48: RED RIVER | U48: 1308 | V48: 24 | W48: 1720742.7 | X48: 661438.82
A49: 25587 | B49: 43041 | C49: Trash - Curbside/Alley Missed Pickup | D49: MISSED TRASH CHECK FOR OTHERS ALSO MISSED CURB | E49: 101 Westover Park Ct | F49: =SEARCH($G$1,D49,1) -> #VALUE! | G49: =SEARCH($G$1,D49,1) -> #VALUE! | S49: 37215 | T49: RED RIVER | U49: 3305S | V49: 25 | W49: 1729295.5 | X49: 644211.6
A50: 25588 | B50: 43041 | C50: Trash Collection Complaint | D50: Missed says it has happened numerous times and she is upset. wants Supervisor to call her. | E50: 201 Channelkirk Ln | F50: =SEARCH($G$1,D50,1) -> #VALUE! | G50: =SEARCH($G$1,D50,1) -> #VALUE! | S50: 37215 | T50: RED RIVER | U50: 3305 | V50: 25 | W50: 1729536.8 | X50: 648641.9
A51: 25592 | B51: 43041 | C51: Trash - Curbside/Alley Missed Pickup | D51: Missed pickup; cust says trash is missed once a month | E51: 205 Channelkirk Ln | F51: =SEARCH($G$1,D51,1) -> #VALUE! | G51: =SEARCH($G$1,D51,1) -> #VALUE! | S51: 37215 | T51: RED RIVER | U51: 3305 | V51: 25 | W51: 1729610.5 | X51: 648595.97
A52: 25593 | B52: 43041 | C52: Trash - Curbside/Alley Missed Pickup | D52: New resident, trash missed 2 weeks in a row | E52: 4309 Lone Oak Rd | F52: =SEARCH($G$1,D52,1) -> #VALUE! | G52: =SEARCH($G$1,D52,1) -> #VALUE! | S52: 37215 | T52: RED RIVER | U52: 3305 | V52: 25 | W52: 1729234.8 | X52: 643478.25
A53: 25594 | B53: 43041 | C53: Trash - Curbside/Alley Missed Pickup | D53: Missed entire alley | E53: 4507 Nevada Ave | F53: =SEARCH($G$1,D53,1) -> #VALUE! | G53: =SEARCH($G$1,D53,1) -> #VALUE! | S53: 37209 | T53: RED RIVER | U53: 1308 | V53: 24 | W53: 1720021.8 | X53: 661789.6
A54: 25606 | B54: 43041 | C54: Trash - Curbside/Alley Missed Pickup | D54: Missed pickup | E54: 3012 Sunnyview Ct | F54: =SEARCH($G$1,D54,1) -> #VALUE! | G54: =SEARCH($G$1,D54,1) -> #VALUE! | S54: 37218 | T54: RED RIVER | U54: 3204 | V54: 1 | W54: 1724135.7 | X54: 690902.4
A55: 25653 | B55: 43041 | C55: Trash - Curbside/Alley Missed Pickup | D55: missed the entire street | E55: 118 WESTOVER PARK CT | F55: =SEARCH($G$1,D55,1) -> #VALUE! | G55: =SEARCH($G$1,D55,1) -> #VALUE! | S55: 37215 | T55: RED RIVER | U55: 3305S | V55: 25 | W55: 1728948 | X55: 644353.07
...

Sheet Sheet1
A1: Trash Route | B1: count
A2: 3205 | B2: =COUNTIF(trash_hauler_report!U:U,Sheet1!A2) -> 145
A3: 4202 | B3: =COUNTIF(trash_hauler_report!U:U,Sheet1!A3) -> 178
A4: 4205 | B4: =COUNTIF(trash_hauler_report!U:U,Sheet1!A4) -> 72
A5: 2206 | B5: =COUNTIF(trash_hauler_report!U:U,Sheet1!A5) -> 102
A6: 4203 | B6: =COUNTIF(trash_hauler_report!U:U,Sheet1!A6) -> 240
A7: 4304 | B7: =COUNTIF(trash_hauler_report!U:U,Sheet1!A7) -> 267
A8: 3303 | B8: =COUNTIF(trash_hauler_report!U:U,Sheet1!A8) -> 226
A9: 9208 | B9: =COUNTIF(trash_hauler_report!U:U,Sheet1!A9) -> 233
A10: 4210 | B10: =COUNTIF(trash_hauler_report!U:U,Sheet1!A10) -> 35
A11: 4204 | B11: =COUNTIF(trash_hauler_report!U:U,Sheet1!A11) -> 192
A12: 3201 | B12: =COUNTIF(trash_hauler_report!U:U,Sheet1!A12) -> 253
A13: 9207 | B13: =COUNTIF(trash_hauler_report!U:U,Sheet1!A13) -> 84
... A27: 9303 | B27: =COUNTIF(trash_hauler_report!U:U,Sheet1!A27) -> 267
A28: 2303S | B28: =COUNTIF(trash_hauler_report!U:U,Sheet1!A28) -> 24
A29: 3305S | B29: =COUNTIF(trash_hauler_report!U:U,Sheet1!A29) -> 15
A30: 1309 | B30: =COUNTIF(trash_hauler_report!U:U,Sheet1!A30) -> 50
A31: 3504 | B31: =COUNTIF(trash_hauler_report!U:U,Sheet1!A31) -> 161
A32: 9203 | B32: =COUNTIF(trash_hauler_report!U:U,Sheet1!A32) -> 241
A33: 4305 | B33: =COUNTIF(trash_hauler_report!U:U,Sheet1!A33) -> 131
A34: 4403 | B34: =COUNTIF(trash_hauler_report!U:U,Sheet1!A34) -> 190
A35: 4505 | B35: =COUNTIF(trash_hauler_report!U:U,Sheet1!A35) -> 101
A36: 1401 | B36: =COUNTIF(trash_hauler_report!U:U,Sheet1!A36) -> 67
A37: 9401 | B37: =COUNTIF(trash_hauler_report!U:U,Sheet1!A37) -> 101
A38: 3404 | B38: =COUNTIF(trash_hauler_report!U:U,Sheet1!A38) -> 106
A39: 3401 | B39: =COUNTIF(trash_hauler_report!U:U,Sheet1!A39) -> 164
A40: 3301S | B40: =COUNTIF(trash_hauler_report!U:U,Sheet1!A40) -> 4
A41: 3302S | B41: =COUNTIF(trash_hauler_report!U:U,Sheet1!A41) -> 23
A42: 2403 | B42: =COUNTIF(trash_hauler_report!U:U,Sheet1!A42) -> 138
A43: 1404 | B43: =COUNTIF(trash_hauler_report!U:U,Sheet1!A43) -> 88
A44: 1504 | B44: =COUNTIF(trash_hauler_report!U:U,Sheet1!A44) -> 136
A45: 4401 | B45: =COUNTIF(trash_hauler_report!U:U,Sheet1!A45) -> 78
A46: 9508 | B46: =COUNTIF(trash_hauler_report!U:U,Sheet1!A46) -> 140
A47: 3203 | B47: =COUNTIF(trash_hauler_report!U:U,Sheet1!A47) -> 262
A48: 4504 | B48: =COUNTIF(trash_hauler_report!U:U,Sheet1!A48) -> 359
A49: 4402 | B49: =COUNTIF(trash_hauler_report!U:U,Sheet1!A49) -> 115
A50: 2505 | B50: =COUNTIF(trash_hauler_report!U:U,Sheet1!A50) -> 218
A51: 2501 | B51: =COUNTIF(trash_hauler_report!U:U,Sheet1!A51) -> 116
A52: 2509 | B52: =COUNTIF(trash_hauler_report!U:U,Sheet1!A52) -> 87
A53: 9504 | B53: =COUNTIF(trash_hauler_report!U:U,Sheet1!A53) -> 59
...

Sheet Sheet4
A1: Trash Route | B1: count
A2: 4504 | B2: 359
A3: 3302 | B3: 310
A4: 1303 | B4: 286
A5: 1301 | B5: 275
A6: 4404 | B6: 274
A7: 1304 | B7: 273
A8: 4304 | B8: 267
A9: 9303 | B9: 267
A10: 3203 | B10: 262
A11: 3412 | B11: 255
A12: 3305 | B12: 254
A13: 3201 | B13: 253
... A125: 1308 | B125: 58
A126: 4203S | B126: 58
A127: 9204 | B127: 55
A128: 9206 | B128: 54
A129: 9306 | B129: 54
A130: 1309 | B130: 50
A131: 1405 | B131: 50
A132: 2402 | B132: 49
A133: 9301 | B133: 49
A134: 2305S | B134: 47
A135: 2408 | B135: 46
A136: 4310 | B136: 46
A137: 3304S | B137: 45
A138: 1205 | B138: 45
A139: 2306 | B139: 44
A140: 3206 | B140: 42
A141: 9501 | B141: 39
A142: 4508 | B142: 39
A143: 4410 | B143: 39
A144: 4210 | B144: 35
A145: 9405 | B145: 34
A146: 1302S | B146: 34
A147: 4506 | B147: 31
A148: 3406 | B148: 28
A149: 2304S | B149: 27
A150: 4209 | B150: 27
A151: 2303S | B151: 24
...

Sheet Sheet2
A1: Incident Address
A2: 3817 Crouch Dr | B2: =COUNTIF(trash_hauler_report!$E$2:$E$20227,Sheet2!A2) -> 1
A3: 4028 Clarksville Pike | B3: =COUNTIF(trash_hauler_report!$E$2:$E$20227,Sheet2!A3) -> 3
A4: 6528 Thunderbird Dr | B4: =COUNTIF(trash_hauler_report!$E$2:$E$20227,Sheet2!A4) -> 1
A5: 2603 old matthews rd | B5: =COUNTIF(trash_hauler_report!$E$2:$E$20227,Sheet2!A5) -> 1
A6: 604 croley dr | B6: =COUNTIF(trash_hauler_report!$E$2:$E$20227,Sheet2!A6) -> 1
A7: 3602 floral dr | B7: =COUNTIF(trash_hauler_report!$E$2:$E$20227,Sheet2!A7) -> 5
A8: 4721 Chalmers Dr | B8: =COUNTIF(trash_hauler_report!$E$2:$E$20227,Sheet2!A8) -> 1
A9: 1816 Jo Johnston Ave | B9: =COUNTIF(trash_hauler_report!$E$2:$E$20227,Sheet2!A9) -> 18
A10: 4484 Lavergne Couchville Pike | B10: =COUNTIF(trash_hauler_report!$E$2:$E$20227,Sheet2!A10) -> 1
A11: 1206 Ireland St | B11: =COUNTIF(trash_hauler_report!$E$2:$E$20227,Sheet2!A11) -> 1
A12: 3113 HYDES FERRY RD | B12: =COUNTIF(trash_hauler_report!$E$2:$E$20227,Sheet2!A12) -> 1
A13: 3210 Whites Creek Pike | B13: =COUNTIF(trash_hauler_report!$E$2:$E$20227,Sheet2!A13) -> 9
... A4390: 2322 Modena Dr | B4390: =COUNTIF(trash_hauler_report!$E$2:$E$20227,Sheet2!A4390) -> 1
A4391: 107 | B4391: =COUNTIF(trash_hauler_report!$E$2:$E$20227,Sheet2!A4391) -> 1
A4392: 6004 Monroe Xing | B4392: =COUNTIF(trash_hauler_report!$E$2:$E$20227,Sheet2!A4392) -> 1
A4393: 717 Ansley Ct | B4393: =COUNTIF(trash_hauler_report!$E$2:$E$20227,Sheet2!A4393) -> 1
A4394: 1919 Blair Blvd | B4394: =COUNTIF(trash_hauler_report!$E$2:$E$20227,Sheet2!A4394) -> 3
A4395: 312 NEELYS BEND RD | B4395: =COUNTIF(trash_hauler_report!$E$2:$E$20227,Sheet2!A4395) -> 6
A4396: 4149 Highlander Ct | B4396: =COUNTIF(trash_hauler_report!$E$2:$E$20227,Sheet2!A4396) -> 1
A4397: 1227 Kirkland Ave | B4397: =COUNTIF(trash_hauler_report!$E$2:$E$20227,Sheet2!A4397) -> 1
A4398: 1612 Porter Ave | B4398: =COUNTIF(trash_hauler_report!$E$2:$E$20227,Sheet2!A4398) -> 2
A4399: 429 Franklin Limestone Rd | B4399: =COUNTIF(trash_hauler_report!$E$2:$E$20227,Sheet2!A4399) -> 2
A4400: 2321 23rd Ave N | B4400: =COUNTIF(trash_hauler_report!$E$2:$E$20227,Sheet2!A4400) -> 2
A4401: 1612 24TH AVE N | B4401: =COUNTIF(trash_hauler_report!$E$2:$E$20227,Sheet2!A4401) -> 2
A4402: 912 38th Ave N | B4402: =COUNTIF(trash_hauler_report!$E$2:$E$20227,Sheet2!A4402) -> 2
A4403: 716 EBENWAY DR | B4403: =COUNTIF(trash_hauler_report!$E$2:$E$20227,Sheet2!A4403) -> 1
... A12381: 604 Somerset Ct | B12381: =COUNTIF(trash_hauler_report!$E$2:$E$20227,Sheet2!A12381) -> 1

Sheet Sheet3
A1: Incident | B1: Address
A2: 3817 | B2: Crouch | C2: Dr
A3: 4028 | B3: Clarksville | C3: Pike
A4: 6528 | B4: Thunderbird | C4: Dr
A5: 2603 | B5: old | C5: matthews | D5: rd
A6: 604 | B6: croley | C6: dr
A7: 3602 | B7: floral | C7: dr
A8: 4721 | B8: Chalmers | C8: Dr
A9: 1816 | B9: Jo | C9: Johnston | D9: Ave
A10: 4484 | B10: Lavergne | C10: Couchville | D10: Pike
A11: 1206 | B11: Ireland | C11: St
A12: 3113 | B12: HYDES | C12: FERRY | D12: RD
A13: 3210 | B13: Whites | C13: Creek | D13: Pike
A14: 830 | B14: Meridian | C14: St
A15: 2200 | B15: osage | C15: st
A16: 6543 | B16: Thunderbird | C16: Dr
A17: 2218 | B17: BUENA | C17: VISTA | D17: PIKE
A18: 2720 | B18: riverbend | C18: dr
A19: 4209 | B19: Lone | C19: Oak | D19: Rd
A20: 356 | B20: Kingview | C20: Dr
A21: 449 | B21: Westboro | C21: Dr
A22: 1414 | B22: Old | C22: Hickory | D22: Blvd
A23: 117 | B23: Lafayette | C23: Ct
A24: 1904 | B24: MeHarry | C24: Blvd
A25: 1144 | B25: Sewanee | C25: Rd
A26: 1815 | B26: WOODMONT | C26: BLVD
A27: 405 | B27: Page | C27: Rd
A28: 4722 | B28: DANBY | C28: DR
A29: 2812 | B29: 27TH | C29: AVE | D29: S
A30: 4506 | B30: DAKOTA | C30: AVE
A31: 259 | B31: Sunrise | C31: Ave
A32: 4311 | B32: dakota | C32: ave
A33: 4029 | B33: Graybar | C33: Ct
A34: 524 | B34: Harding | C34: Pl
A35: 3702 | B35: Hobbs | C35: Rd
A36: 405 | B36: brook | C36: hollow | D36: rd
A37: 162 | B37: antioch | C37: pike
A38: 131 | B38: page | C38: rd
A39: 3704 | B39: Hobbs | C39: Rd
A40: 6011 | B40: Jocelyn | C40: Hollow | D40: Rd
...

Sheet trash_hauler_report_project_not
A1: MISSED | B1: OTHERS
A2: missed | B2: damaged | C2: email reminder | D2: supverisor | E2: close lid | F2: backdoor service? | G2: full trash | H2: trash scattered
A3: miss
A4: skip | C4: word map of the 'not missed trash'
A5: skipped
A6: not picked
A7: picked up
A8: failed
A9: did not
A10: fail
A11: failed
A12: forgot
A13: never
